nohup: ignoring input
Working dir: /root/CoTFaithChecker
Working dir: /root/CoTFaithChecker
Working dir: /root/CoTFaithChecker
Working dir: /root/CoTFaithChecker
Traceback (most recent call last):
  File "/root/CoTFaithChecker/i_probe_steer/main/xyyx_probing.py", line 47, in <module>
    print(f"on host {socket.gethostname()} (PID {os.getpid()}) ===",)
NameError: name 'socket' is not defined
Traceback (most recent call last):
  File "/root/CoTFaithChecker/i_probe_steer/main/xyyx_probing.py", line 47, in <module>
    print(f"on host {socket.gethostname()} (PID {os.getpid()}) ===",)
NameError: name 'socket' is not defined
Traceback (most recent call last):
  File "/root/CoTFaithChecker/i_probe_steer/main/xyyx_probing.py", line 47, in <module>
    print(f"on host {socket.gethostname()} (PID {os.getpid()}) ===",)
NameError: name 'socket' is not defined
Traceback (most recent call last):
  File "/root/CoTFaithChecker/i_probe_steer/main/xyyx_probing.py", line 47, in <module>
    print(f"on host {socket.gethostname()} (PID {os.getpid()}) ===",)
NameError: name 'socket' is not defined
W0502 21:51:07.267000 3415 torch/distributed/elastic/multiprocessing/api.py:897] Sending process 3608 closing signal SIGTERM
W0502 21:51:07.268000 3415 torch/distributed/elastic/multiprocessing/api.py:897] Sending process 3610 closing signal SIGTERM
E0502 21:51:07.383000 3415 torch/distributed/elastic/multiprocessing/api.py:869] failed (exitcode: 1) local_rank: 0 (pid: 3607) of binary: /usr/bin/python3
Traceback (most recent call last):
  File "/usr/local/bin/accelerate", line 8, in <module>
    sys.exit(main())
  File "/usr/local/lib/python3.10/dist-packages/accelerate/commands/accelerate_cli.py", line 50, in main
    args.func(args)
  File "/usr/local/lib/python3.10/dist-packages/accelerate/commands/launch.py", line 1204, in launch_command
    multi_gpu_launcher(args)
  File "/usr/local/lib/python3.10/dist-packages/accelerate/commands/launch.py", line 825, in multi_gpu_launcher
    distrib_run.run(args)
  File "/usr/local/lib/python3.10/dist-packages/torch/distributed/run.py", line 910, in run
    elastic_launch(
  File "/usr/local/lib/python3.10/dist-packages/torch/distributed/launcher/api.py", line 138, in __call__
    return launch_agent(self._config, self._entrypoint, list(args))
  File "/usr/local/lib/python3.10/dist-packages/torch/distributed/launcher/api.py", line 269, in launch_agent
    raise ChildFailedError(
torch.distributed.elastic.multiprocessing.errors.ChildFailedError: 
============================================================
i_probe_steer/main/xyyx_probing.py FAILED
------------------------------------------------------------
Failures:
[1]:
  time      : 2025-05-02_21:51:07
  host      : fd4b7fbca240
  rank      : 2 (local_rank: 2)
  exitcode  : 1 (pid: 3609)
  error_file: <N/A>
  traceback : To enable traceback see: https://pytorch.org/docs/stable/elastic/errors.html
------------------------------------------------------------
Root Cause (first observed failure):
[0]:
  time      : 2025-05-02_21:51:07
  host      : fd4b7fbca240
  rank      : 0 (local_rank: 0)
  exitcode  : 1 (pid: 3607)
  error_file: <N/A>
  traceback : To enable traceback see: https://pytorch.org/docs/stable/elastic/errors.html
============================================================
